{
  "nbformat": 4,
  "nbformat_minor": 0,
  "metadata": {
    "colab": {
      "provenance": [],
      "gpuType": "T4",
      "authorship_tag": "ABX9TyNL3riIJ/MlwN5/WNx49k6R",
      "include_colab_link": true
    },
    "kernelspec": {
      "name": "python3",
      "display_name": "Python 3"
    },
    "language_info": {
      "name": "python"
    },
    "accelerator": "GPU"
  },
  "cells": [
    {
      "cell_type": "markdown",
      "metadata": {
        "id": "view-in-github",
        "colab_type": "text"
      },
      "source": [
        "<a href=\"https://colab.research.google.com/github/nayiarmiharbi/ColabG/blob/main/TensorFlow_Begin.ipynb\" target=\"_parent\"><img src=\"https://colab.research.google.com/assets/colab-badge.svg\" alt=\"Open In Colab\"/></a>"
      ]
    },
    {
      "cell_type": "code",
      "source": [
        "!pip install tensorflow-gpu"
      ],
      "metadata": {
        "id": "DJmeP9_XoPaJ",
        "colab": {
          "base_uri": "https://localhost:8080/"
        },
        "outputId": "5463963f-6fd4-4740-91bb-b61145fff103"
      },
      "execution_count": null,
      "outputs": [
        {
          "output_type": "stream",
          "name": "stdout",
          "text": [
            "Collecting tensorflow-gpu\n",
            "  Downloading tensorflow-gpu-2.12.0.tar.gz (2.6 kB)\n",
            "  \u001b[1;31merror\u001b[0m: \u001b[1msubprocess-exited-with-error\u001b[0m\n",
            "  \n",
            "  \u001b[31m×\u001b[0m \u001b[32mpython setup.py egg_info\u001b[0m did not run successfully.\n",
            "  \u001b[31m│\u001b[0m exit code: \u001b[1;36m1\u001b[0m\n",
            "  \u001b[31m╰─>\u001b[0m See above for output.\n",
            "  \n",
            "  \u001b[1;35mnote\u001b[0m: This error originates from a subprocess, and is likely not a problem with pip.\n",
            "  Preparing metadata (setup.py) ... \u001b[?25l\u001b[?25herror\n",
            "\u001b[1;31merror\u001b[0m: \u001b[1mmetadata-generation-failed\u001b[0m\n",
            "\n",
            "\u001b[31m×\u001b[0m Encountered error while generating package metadata.\n",
            "\u001b[31m╰─>\u001b[0m See above for output.\n",
            "\n",
            "\u001b[1;35mnote\u001b[0m: This is an issue with the package mentioned above, not pip.\n",
            "\u001b[1;36mhint\u001b[0m: See above for details.\n"
          ]
        }
      ]
    },
    {
      "cell_type": "code",
      "source": [
        "import tensorflow as tf\n",
        "print(tf.__version__)"
      ],
      "metadata": {
        "colab": {
          "base_uri": "https://localhost:8080/"
        },
        "id": "p1WThkdMtdVX",
        "outputId": "3ef2f3c2-9c0c-4e73-b5bc-6d91788fe839"
      },
      "execution_count": null,
      "outputs": [
        {
          "output_type": "stream",
          "name": "stdout",
          "text": [
            "2.18.0\n"
          ]
        }
      ]
    },
    {
      "cell_type": "code",
      "source": [],
      "metadata": {
        "id": "XTNY-yh_tsIg"
      },
      "execution_count": null,
      "outputs": []
    }
  ]
}